Workbook
Name _1.전기공사: #REF!
Name _1.전기공사: #REF!
Name _A100000: #REF!
Name _A100000: #REF!
Name _A66000: #REF!
Name _A66000: #REF!
Name _A67000: #REF!
Name _A67000: #REF!
Name _A68000: #REF!
Name _A68000: #REF!
Name _A80000: #REF!
Name _A80000: #REF!
Name _zz1: #REF!
Name _zz1: #REF!
Name a: #REF!
Name a: #REF!
Name aaa: #REF!
Name aaa: #REF!
Name aaaaaaaaaaaaaa: #REF!
Name aaaaaaaaaaaaaa: #REF!
Name ABC: #REF!,#REF!
Name ABC: '[1]플랜트 설치'!$A$1:$A$65536,'[1]플랜트 설치'!$A$1:$IV$2
Name AS: #REF!,#REF!
Name AS: '[2]플랜트 설치'!$A$1:$A$65536,'[2]플랜트 설치'!$A$1:$IV$2
Name AUAcºn: #REF!
Name AUAcºn: [3]교통대책내역!#REF!
Name Client: #REF!
Name Client: #REF!
Name CM: #REF!
Name CM: #REF!
Name cse: #REF!
Name cse: #REF!
Name DATABASE1: #REF!
Name DATABASE1: #REF!
Name Date_Bidding: #REF!
Name Date_Bidding: #REF!
Name ddq: #REF!,#REF!
Name ddq: '[4]플랜트 설치'!$A$1:$A$65536,'[4]플랜트 설치'!$A$1:$IV$2
Name Document_array: {"Book1","01-1월자금청구.xls"}
Name Document_array: {"Book1","01-1월자금청구.xls"}
Name DROW: #N/A
Name ek: #REF!
Name ek: #REF!
Name eorn1: #REF!
Name eorn1: [5]견적서!#REF!
Name Exchange_Rate: #REF!
Name Exchange_Rate: #REF!
Name extract1: #REF!
Name extract1: #REF!
Name f: #REF!
Name f: #REF!
Name fgf: #REF!
Name fgf: #REF!
Name gidtlr: #REF!
Name gidtlr: #REF!
Name J: #REF!
Name J: [6]!매크로19
Name JL: #REF!,#REF!
Name JL: '[7]플랜트 설치'!$A$1:$A$65536,'[7]플랜트 설치'!$A$1:$IV$2
Name lw: #REF!

Sheet 개요
A2: 1 | B2: 대상 시설 개요
A3: 구분 | B3: 에이앤비
A4: 1.1 단지명 | B4: 탄현지구미주8차
B5: 시설물 정기안전점검 견적서 | C5: (2023년 하반기)
A7: 1.2 용역내용 | B7: 상기 금액은 하반기 정기안전점검 용역대가임.
A8: 1.2 소재지
A9: 1.3 견적일짜
A10: 1.4 계약성 작성일 | B10: 2023년
A11: 1.4 단지규모 | B11: 지하1층~지상13층(연면적 : 29,369.45m²)
B12: 공동주택
A13: 1.4 사용승인일 | B13: 1991년 09월 05일
A14: 1.5 전화 | B14: 전화 : 031-921-7058
A15: 1.6 팩스
A17: 2 | B17: 용역 범위/용역금액 및 지불조건
A18: 2.1 용역범위
A19: 2.1 견적 금액 | B19: 2600000

Sheet 에이앤비 갑지
B7: =개요!B5 -> 시설물 정기안전점검 견적서
B9: =개요!B4 -> 탄현지구미주8차
B20: =개요!B9 -> 0
F26: ㈜ 에이앤비 대표이사 (인)
F27: 경기도 용인시 기흥구 마북로 159 한성프라자 207호(마북동 )
F28: TEL : 031)283-3328 FAX : 031)284-3328
C32: 1 | D32: 대상 시설 개요
D33: 1.1 단 지 명 : | G33: =개요!B4 -> 탄현지구미주8차
D34: 1.2 소 재 지 : | G34: =개요!B8 -> 0
D35: 1.3 단지 규모 : | G35: =개요!B11 -> 지하1층~지상13층(연면적 : 29,369.45m²)
D36: 1.4 사용승인일 : | G36: =개요!B13 -> 1991년 09월 05일
C38: 2 | D38: 용역 범위 / 용역금액 및 지불조건
D39: 2.1 용역범위
D40: 가) 시설물의 안전 및 유지관리에 관한 특별법 제11조에 의거한 건축물 정기안전점검
D41: 나) 정기안전점검 보고서 제출 및 시설물통합정보관리시스템 FMS결과 자료 입력
D43: 2.2 용역금액 및 지불조건 | I43: (2023년 하반기 정기안전점검 1회 금액)
D44: 가) 용 역 금 액 : | G44: =대가산출!D3 -> 일금 이백육십만원정(₩2,600,000) - VAT 별도
D45: 나) 지 불 조 건 : 정기안전점검보고서 납품(FMS 자료입력)후 10일내 지불조건
C48: 3 | D48: 과업 수행 기간 : 7일

Sheet 대가산출
B1: 정기안전점검 (하반기) 용역
H2: =개요!B11 -> 지하1층~지상13층(연면적 : 29,369.45m²)
B3: 총 용 역 비 | D3: 일금 이백육십만원정(₩2,600,000) - VAT 별도
B4: 공급가액 | D4: ="일금 "&NUMBERSTRING(H29,1)&"원정"&TEXT(H29,"(￦ #,##0)")&" " -> #N/A
B5: 부가가치세 | D5: ="일금 "&NUMBERSTRING(H30,1)&"원정"&TEXT(H30,"(￦ #,##0)")&" " -> #VALUE!
B6: 산 출 내 역 서
B7: 구 분 | D7: 기술자등급 | E7: 단 가 | F7: 단 위 | G7: 인 원 | H7: 금 액 | I7: 비 고
B8: 1. 직 접 인 건 비 | H8: =INT(SUM(H9,H10,H11,H12,H13,H14,H15,H16)) -> 2170880 | I8: 인원은 변경될수 있음
C9: 가.외업 | D9: 특급기술자 | E9: 335638 | F9: 인·일 | G9: 1 | H9: =INT(E9*G9) -> 335638
D10: 고급기술자 | E10: 282545 | F10: 인·일 | G10: 1 | H10: =INT(E10*G10) -> 282545
D11: 중급기술자 | E11: 261571 | F11: 인·일 | G11: 1 | H11: =INT(E11*G11) -> 261571
D12: 초급기술자 | E12: 205686 | F12: 인·일 | G12: 1 | H12: =INT(E12*G12) -> 205686
C13: 나.내업 | D13: 특급기술자 | E13: 335638 | F13: 인·일 | G13: 1 | H13: =INT(E13*G13) -> 335638
D14: 고급기술자 | E14: 282545 | F14: 인·일 | G14: 1 | H14: =INT(E14*G14) -> 282545
D15: 중급기술자 | E15: 261571 | F15: 인·일 | G15: 1 | H15: =INT(E15*G15) -> 261571
D16: 초급기술자 | E16: 205686 | F16: 인·일 | G16: 1 | H16: =INT(E16*G16) -> 205686
B17: 2. 제 경 비 | F17: % | G17: 5 | H17: =ROUND(H8*G17%, 0) -> 108544 | I17: 직접인건비 * 5%
B18: 3. 기 술 료 | F18: % | G18: 5 | H18: =ROUND((H8+H17)*G18%, 0) -> 113971 | I18: (직접인건비 * 제경비) * 5%
B19: 4. 직 접 경 비 | H19: =INT(SUM(H21,H22,H23,H24,H25,)) -> 181961
B20: 가. 체재비 및 차량비
B21: (1) 여비 및 현장체재비 | E21: 20000 | F21: 1 | H21: =G21*E21*F21 -> 0
B22: (2) 차량운행비 | E22: 10000 | F22: 1 | H22: =G22*E22*F22 -> 0
B23: (3) 위험수당 | F23: % | G23: 8 | H23: =ROUND((SUM(H9:H12))*G23%, 0) -> 86835 | I23: 외업인건비의 8%
B24: (4) 기계기구손료 | F24: % | G24: 3 | H24: =ROUND(H8*G24%, 0) -> 65126 | I24: 직접인건비의 3%
B25: (5) 인쇄비 | E25: 30000 | F25: 식 | G25: 1 | H25: =INT(G25*E25) -> 30000
B26: 5. 조 정 비 | H26: =INT(SUM(H8,H17,H18,H19)*0) -> 0 | I26: 구조형식,용도,경과년수
B27: 6. 합 계 금 액 | D27: ( 1 + 2 + 3 + 4 ) | H27: =(SUM(H8,H17,H18,H19,H26)) -> 2575356
B28: 절 삭 금 액 | H28: 65356
B29: 공 급 가 액 | H29: =H27-H28 -> 2510000
B30: 부가가치세 | H30: 별도
B31: 견 적 금 액 | H31: =H29 -> 2510000 | I31: 부가세 별도
D32: ㈜ 에 이 앤 비
D33: 사업자등록번호 : 863-87-00907 | I33: ※ 특이사항
D34: 경기도 용인시 기흥구 마북로 159 (한성프라자 207호) | I34: 견적서 유효기간
D35: 대 표 이 사 서 응 원 (인) | I35: 발행일로부터
D36: 전화번호 : 031-283-3328 담당자 : 이 현 희 실장 | I36: 30일입니다.

Sheet 계약서1
B7: 사우
B8: 정기안전점검 용역 계약서
B9: 서희아리채
B16: 2025년 상반기
I23: ㈜ 에이앤비
I24: 경기도 용인시 기흥구 마북로 159 한성프라자 207호
I25: 전화 : 031-283-3328 팩스 :031-284-3328
B30: 시설물의 정기안전점검 표준계약서
B31: 계 약 자 | D31: 관 리 주 체 | G31: =B9 -> 서희아리채
D32: 계약상대자 | G32: ● 상호또는법인명 : (주)에이앤비
G33: ● 사업자등록번호 : 863-87-00907
G34: ● 주 소 : 경기도 용인시 기흥구 마북로 159 한성프라자 207호
G35: ● 전화번호 : 031-283-3328 팩스번호 : 031-284-3328
G36: ● 대 표 자 : 서 응 원
B37: 계 약 내 용 | D37: 계 약 건 명 | G37: 서희아리채 정기안전점검 용역
D38: 계 약 금 액 | G38: 일금 칠십만원정(₩ 700,000) - VAT 별도
D39: 공 급 가 액 | G39: 일금 칠십만원정(₩ 700,000)
D40: 부가 가치세 | G40: 10% 별도
D41: 계 약 기 간 | G41: 2025 . . . ~ 2025 . . .
D42: 위 치 | G42: 경기도 안양시 만안구 문예로52번길 19 (안양동)
G43: 전화 : 031-465-6674 , 팩스 : 031-465-6679
D44: 보고서 납품 | G44: 시설물통합정보시스템(FMS)등록 후 정기안전점검 보고서 1부
D45: 기 타 사 항 | G45: 상기 금액은 2025년 상반기 정기안전점검 용역대가임.
B47: 관리주체와 계약상대자는 상호 대등한 입장에서 붙임의 계약문서에 의하여 위와 같이 계약을 체결하고 신의에 따라 성실히 계약상의 의무를 이행할 것을 확약하며, 이 계약의 증거로서 계약서를 작성하여 당사자가 기명날인한 후 각각 1통씩 보관한다.
B49: 붙 임 서 류 : | E49: 1. 시설물의 정기안전점검 표준계약조건 1부.
E50: 2. 시설물의 정기안전점검 과업내용 1부.
E51: 3. 시설물의 정기안전점검 대가산출 내역서 1부.
B53: 계 약 일 자 : | E53: 2025년
B54: 관 리 주 체(발 주 자) | L54: 계 약 상 대 자(수 주 자)
B55: 상 호 : | E55: =B9 -> 서희아리채 | L55: 상 호 : | O55: ㈜ 에 이 앤 비
B56: 주 소 : | E56: =G42 -> 경기도 안양시 만안구 문예로52번길 19 (안양동) | L56: 주 소 : | O56: 경기도 용인시 기흥구 마북로 159 한성프라자 207호
B57: 관리소장 : | E57: (인) | L57: 대표이사 : | O57: 서 응 원 (인)
B58: <붙임 1>
B59: 시설물의 정기안전점검 표준계약조건
B61: 「시설물의 안전 및 유지관리에 관한 특별법」(이하 “시설물안전법”이라 한다) 제11조, 시행령
B62: 제8조 및 동법 제12조의 규정에 따라 | I62: =B9 -> 서희아리채 | N62: (이하"발주자"라 한다)와
B63: 정기안전점검의 실시자인 ㈜에이앤비(이하 "수주자"라 한다)는 다음과 같이 계약을 체결한다.
B65: 제1조(목적)
C66: 이 계약은 "발주자"가 관리하고 있는 시설물에 대하여 "수주자"는 정기안전점검을 실시하여 구조적・기능적 결함을 발견하고, 그에 대한 신속하고 적절한 조치를 취하기 위하여 구조적 안전성 및 결함의 원인 등을 조사・측정・평가하고 보수・보강 등의 방법을 제시함으로써 재해 및 재난을 예방하고 시설물의 효용증진과 공공의 안전을 확보하는데 그 목적이 있다.
B68: 제2조(점검의 범위) 정기안전점검의 범위는 다음과 같다.
...
